Workbook

Sheet フォームの回答
A1: タイムスタンプ | B1: 問１ お子様は何年生ですか。 | C1: 未就学 | D1: 小学校 | E1: 中学校 | F1: 卒業 | G1: 問２ 11月22日（ふれあいホリデー）はお子様と一緒に過ごされましたか。 | H1: 問３−Ａ１ 主にどのように過ごされましたか。 | I1: 問３－Ａ２ 前の問い（ 問３－Ａ１）で回答された内容について具体的に記入してください。 | J1: 問３−Ｂ１ お子様はどのように過ごされましたか。 | K1: 問４ あなたは休暇を取得されましたか | L1: 問４－１ 「取得していない」と回答いただいた方は、次のどれにあたりますか。 | M1: 職場で推奨されたが取得しなかった | N1: 業務多忙で取得できなかった | O1: 自営業だから | P1: 取得するつもりはなかった | Q1: 取得しにくかった | R1: 勤務日ではなかった | S1: 問４－２ 前の問（問４－１）で「取得するつもりはなかった」または「取得しにくかった」と回答いただいた方は、理由等をお答えください。 | T1: 問５ 来年度実施する場合、過ごし方について考えを教えてください。 | U1: 問６ 来年度実施する場合、適切な時期について考えを教えてください。 | V1: 問７ 今後に向けてお気づきの点などを教えてください。
A2: 45628.841 | B2: 小学校５年生, 中学校１年生 | C2: =IF(ISERROR(FIND(C$1,$B2)),"×","○") -> × | D2: =IF(ISERROR(FIND(D$1,$B2)),"×","○") -> ○ | E2: =IF(ISERROR(FIND(E$1,$B2)),"×","○") -> ○ | F2: =IF(ISERROR(FIND(F$1,$B2)),"×","○") -> × | G2: 過ごした | H2: 倉吉市内へ出かけた | I2: 散髪、デイサービス | K2: 取得した | M2: =IF(ISERROR(SEARCH(M$1,$L2)),"","○") | N2: =IF(ISERROR(SEARCH(N$1,$L2)),"","○") | O2: =IF(ISERROR(SEARCH(O$1,$L2)),"","○") | P2: =IF(ISERROR(SEARCH(P$1,$L2)),"","○") | Q2: =IF(ISERROR(SEARCH(Q$1,$L2)),"","○") | R2: =IF(ISERROR(SEARCH(R$1,$L2)),"","○") | T2: 体験等に取り組みたいが休暇が取得できるか分からない | U2: ？ | V2: 触れ合い休暇と言っても親が休みにくい。学校行事で休む事も多い。ので休暇取りにくい。
A3: 45625.671 | B3: 中学校３年生 | C3: =IF(ISERROR(FIND(C$1,$B3)),"×","○") -> × | D3: =IF(ISERROR(FIND(D$1,$B3)),"×","○") -> × | E3: =IF(ISERROR(FIND(E$1,$B3)),"×","○") -> ○ | F3: =IF(ISERROR(FIND(F$1,$B3)),"×","○") -> × | G3: 過ごしていない | J3: 子どもだけで過ごした | K3: 取得していない | L3: 業務多忙で取得できなかった | M3: =IF(ISERROR(SEARCH(M$1,$L3)),"","○") | N3: =IF(ISERROR(SEARCH(N$1,$L3)),"","○") -> ○ | O3: =IF(ISERROR(SEARCH(O$1,$L3)),"","○") | P3: =IF(ISERROR(SEARCH(P$1,$L3)),"","○") | Q3: =IF(ISERROR(SEARCH(Q$1,$L3)),"","○") | R3: =IF(ISERROR(SEARCH(R$1,$L3)),"","○") | T3: 体験等に取り組みたいが休暇が取得できるか分からない | U3: 10月
A4: 45625.699 | B4: 小学校２年生 | C4: =IF(ISERROR(FIND(C$1,$B4)),"×","○") -> × | D4: =IF(ISERROR(FIND(D$1,$B4)),"×","○") -> ○ | E4: =IF(ISERROR(FIND(E$1,$B4)),"×","○") -> × | F4: =IF(ISERROR(FIND(F$1,$B4)),"×","○") -> × | G4: 過ごしていない | J4: 放課後児童クラブ等を利用した | K4: 取得していない | L4: 取得するつもりはなかった, 取得しにくかった | M4: =IF(ISERROR(SEARCH(M$1,$L4)),"","○") | N4: =IF(ISERROR(SEARCH(N$1,$L4)),"","○") | O4: =IF(ISERROR(SEARCH(O$1,$L4)),"","○") | P4: =IF(ISERROR(SEARCH(P$1,$L4)),"","○") -> ○ | Q4: =IF(ISERROR(SEARCH(Q$1,$L4)),"","○") -> ○ | R4: =IF(ISERROR(SEARCH(R$1,$L4)),"","○") | S4: 同月に既に参観日やマラソン大会などのために有給を利用していたため。 | T4: 体験等に取り組みたいが休暇が取得できるか分からない | U4: 10月 | V4: 学校の年間行事をみて時期を検討して頂きたい
A5: 45625.701 | B5: 中学校１年生 | C5: =IF(ISERROR(FIND(C$1,$B5)),"×","○") -> × | D5: =IF(ISERROR(FIND(D$1,$B5)),"×","○") -> × | E5: =IF(ISERROR(FIND(E$1,$B5)),"×","○") -> ○ | F5: =IF(ISERROR(FIND(F$1,$B5)),"×","○") -> × | G5: 過ごしていない | J5: 子どもだけで過ごした | K5: 取得していない | L5: 取得するつもりはなかった | M5: =IF(ISERROR(SEARCH(M$1,$L5)),"","○") | N5: =IF(ISERROR(SEARCH(N$1,$L5)),"","○") | O5: =IF(ISERROR(SEARCH(O$1,$L5)),"","○") | P5: =IF(ISERROR(SEARCH(P$1,$L5)),"","○") -> ○ | Q5: =IF(ISERROR(SEARCH(Q$1,$L5)),"","○") | R5: =IF(ISERROR(SEARCH(R$1,$L5)),"","○") | S5: 期末テスト前で三連休になっても出掛ける気にはならないし、親がいても意味がないと感じたから。 | T5: 体験等に取り組みたいが休暇が取得できるか分からない | U5: 10月 | V5: 学校の年間行事をよくみてから時期を決定して頂きたい
A6: 45627.865 | B6: 小学校１年生 | C6: =IF(ISERROR(FIND(C$1,$B6)),"×","○") -> × | D6: =IF(ISERROR(FIND(D$1,$B6)),"×","○") -> ○ | E6: =IF(ISERROR(FIND(E$1,$B6)),"×","○") -> × | F6: =IF(ISERROR(FIND(F$1,$B6)),"×","○") -> × | G6: 過ごした | H6: 倉吉市外へ出かけた | I6: 家族で遊園地に出掛けました | K6: 取得していない | L6: 主婦と、手伝い程度の仕事なので、その日は空いていました | M6: =IF(ISERROR(SEARCH(M$1,$L6)),"","○") | N6: =IF(ISERROR(SEARCH(N$1,$L6)),"","○") | O6: =IF(ISERROR(SEARCH(O$1,$L6)),"","○") | P6: =IF(ISERROR(SEARCH(P$1,$L6)),"","○") | Q6: =IF(ISERROR(SEARCH(Q$1,$L6)),"","○") | R6: =IF(ISERROR(SEARCH(R$1,$L6)),"","○") | T6: イベント等で体験活動に参加したい | U6: 10月 | V6: 学校の行事が多い時期にあたってしまって、妻がその都度、休日を取得して対応してくれていたのですが、さらにもう一つ取得することへの抵抗があり、あまり嬉しい休日ではなかったようです。私も今後、仕事についた時に、子供がひとりで留守番しなくてはならないかもと気がかりななか、更に平日に休日が増えるのは嫌だなという思いです。普段から、休日も平日も遊んでいるので、更に時間を作るのかと悩ましいことだなと思いました。
A7: 45628.703 | B7: 小学校１年生 | C7: =IF(ISERROR(FIND(C$1,$B7)),"×","○") -> × | D7: =IF(ISERROR(FIND(D$1,$B7)),"×","○") -> ○ | E7: =IF(ISERROR(FIND(E$1,$B7)),"×","○") -> × | F7: =IF(ISERROR(FIND(F$1,$B7)),"×","○") -> × | G7: 過ごしていない | J7: 放課後児童クラブ等を利用した | K7: 取得していない | L7: 業務多忙で取得できなかった, 取得するつもりはなかった | M7: =IF(ISERROR(SEARCH(M$1,$L7)),"","○") | N7: =IF(ISERROR(SEARCH(N$1,$L7)),"","○") -> ○ | O7: =IF(ISERROR(SEARCH(O$1,$L7)),"","○") | P7: =IF(ISERROR(SEARCH(P$1,$L7)),"","○") -> ○ | Q7: =IF(ISERROR(SEARCH(Q$1,$L7)),"","○") | R7: =IF(ISERROR(SEARCH(R$1,$L7)),"","○") | S7: 他の用事や看病でで有給休暇を使うので一斉に休みにされても休めない | T7: 体験等に取り組むつもりはない | U7: 10月
A8: 45632.566 | B8: 小学校３年生 | C8: =IF(ISERROR(FIND(C$1,$B8)),"×","○") -> × | D8: =IF(ISERROR(FIND(D$1,$B8)),"×","○") -> ○ | E8: =IF(ISERROR(FIND(E$1,$B8)),"×","○") -> × | F8: =IF(ISERROR(FIND(F$1,$B8)),"×","○") -> × | G8: 過ごした | H8: 倉吉市外へ出かけた | I8: 大阪の美術館に行った | K8: 取得した | M8: =IF(ISERROR(SEARCH(M$1,$L8)),"","○") | N8: =IF(ISERROR(SEARCH(N$1,$L8)),"","○") | O8: =IF(ISERROR(SEARCH(O$1,$L8)),"","○") | P8: =IF(ISERROR(SEARCH(P$1,$L8)),"","○") | Q8: =IF(ISERROR(SEARCH(Q$1,$L8)),"","○") | R8: =IF(ISERROR(SEARCH(R$1,$L8)),"","○") | T8: 体験等に取り組みたいが休暇が取得できるか分からない | U8: 10月～11月の初旬 | V8: この制度を利用できるのは一部の恵まれた家庭だけだと思います。子どもたちの家族の形が1つではないこと、具体的にどのような家庭があるのか、それらをイメージしてください。その上で、その家庭の保護者が休暇を取れるのかを想像してください。 母子家庭の低所得世帯が、すべての家庭で休暇を取得して子どもと過ごせるでしょうか？休暇を取得できなければ、子どもの預け先を探さなくては行けません。学童に預けることになれば、お弁当を作らなくては行けません。 また、家族と過ごせる子とそうでない子の間には精神的な隔たりが生まれてしまいます。 私はフリーランスで仕事をしているため休暇がとれました。しかし、フリーランスは休めば無給です。それだけでなく、翌日以降の業務量が増えます。 個人的にはよい制度だと思えません。来年以降も続けられるのであれば、しっかり議論した上で、保護者に実施する理由を詳しく伝えた上で実施していただきたいと思います。
A9: 45630.802 | B9: 小学校１年生, 中学校１年生, 中学校卒業後 | C9: =IF(ISERROR(FIND(C$1,$B9)),"×","○") -> × | D9: =IF(ISERROR(FIND(D$1,$B9)),"×","○") -> ○ | E9: =IF(ISERROR(FIND(E$1,$B9)),"×","○") -> ○ | F9: =IF(ISERROR(FIND(F$1,$B9)),"×","○") -> ○ | G9: 過ごした | H9: 家庭で過ごした | I9: 家でゆっくりしました。 | K9: 取得していない | L9: 専業主婦なので。 | M9: =IF(ISERROR(SEARCH(M$1,$L9)),"","○") | N9: =IF(ISERROR(SEARCH(N$1,$L9)),"","○") | O9: =IF(ISERROR(SEARCH(O$1,$L9)),"","○") | P9: =IF(ISERROR(SEARCH(P$1,$L9)),"","○") | Q9: =IF(ISERROR(SEARCH(Q$1,$L9)),"","○") | R9: =IF(ISERROR(SEARCH(R$1,$L9)),"","○") | T9: 家庭でふれあいや体験活動等に取り組みたい | U9: 10月ごろ天気もよくてコンサートなど楽しめるイベントがたくさんあるので。 | V9: 10月はたくさんのイベントがありますが。11月はあまりないのでどんなイベントがあるのかまとめて教えてもらいたいです。
A10: 45629.847 | B10: 小学校５年生 | C10: =IF(ISERROR(FIND(C$1,$B10)),"×","○") -> × | D10: =IF(ISERROR(FIND(D$1,$B10)),"×","○") -> ○ | E10: =IF(ISERROR(FIND(E$1,$B10)),"×","○") -> × | F10: =IF(ISERROR(FIND(F$1,$B10)),"×","○") -> × | G10: 過ごした | H10: 倉吉市内へ出かけた | I10: 市役所の窓口に行ったりおばあちゃんの家に行った。 | K10: 取得した | M10: =IF(ISERROR(SEARCH(M$1,$L10)),"","○") | N10: =IF(ISERROR(SEARCH(N$1,$L10)),"","○") | O10: =IF(ISERROR(SEARCH(O$1,$L10)),"","○") | P10: =IF(ISERROR(SEARCH(P$1,$L10)),"","○") | Q10: =IF(ISERROR(SEARCH(Q$1,$L10)),"","○") | R10: =IF(ISERROR(SEARCH(R$1,$L10)),"","○") | T10: 体験等に取り組みたいが休暇が取得できるか分からない | U10: 10月や11月は学校行事が多く、他にも仕事を休む日が多いので、休みにくい。 | V10: 学校行事が少ない時期や祝日がないような月がいい。親全員が休みを取れるわけではないと思う。この取り組みの意図があまりわからない。
A11: 45630.38 | B11: 小学校６年生 | C11: =IF(ISERROR(FIND(C$1,$B11)),"×","○") -> × | D11: =IF(ISERROR(FIND(D$1,$B11)),"×","○") -> ○ | E11: =IF(ISERROR(FIND(E$1,$B11)),"×","○") -> × | F11: =IF(ISERROR(FIND(F$1,$B11)),"×","○") -> × | G11: 過ごしていない | J11: 子どもだけで過ごした | K11: 取得していない | L11: ふれあいホリデーを知ったのが、直前だったため業務を調整できなかった | M11: =IF(ISERROR(SEARCH(M$1,$L11)),"","○") | N11: =IF(ISERROR(SEARCH(N$1,$L11)),"","○") | O11: =IF(ISERROR(SEARCH(O$1,$L11)),"","○") | P11: =IF(ISERROR(SEARCH(P$1,$L11)),"","○") | Q11: =IF(ISERROR(SEARCH(Q$1,$L11)),"","○") | R11: =IF(ISERROR(SEARCH(R$1,$L11)),"","○") | T11: 何か特別な活動に取り組むのではなく、ただただ子どもと一緒にゆっくり過ごしたい。 | U11: 10月以外 | V11: 良い機会だと思ったが、急だったので休みを取ることができなかった。年度はじめなどに、余裕をもって告知をしてもらいたい。(されていたのかもしれないが、実施の数週間前に新聞紙面で知った) ふれあいホリデーの翌週、子どもから「(自分の友達は)みんなお昼ごはんは“ぼっちごはん”だったらしいよ」と言われた。改めて、休みを取って子どもと一緒に過ごしてやりたかったと感じた。 保護者の有給取得促進をねらいのひとつとしてもらうのはありがたいが、児童への教育的配慮に欠ける、大人の都合を子どもたちに押し付けた強引な実施だったように感じる。 このような意見はきっと公表されないんだろうなとも思っている。
A12: 45631.262 | B12: 小学校１年生, 小学校６年生 | C12: =IF(ISERROR(FIND(C$1,$B12)),"×","○") -> × | D12: =IF(ISERROR(FIND(D$1,$B12)),"×","○") -> ○ | E12: =IF(ISERROR(FIND(E$1,$B12)),"×","○") -> × | F12: =IF(ISERROR(FIND(F$1,$B12)),"×","○") -> × | G12: 過ごした | H12: 倉吉市外へ出かけた | I12: 家族旅行 | K12: 取得した | M12: =IF(ISERROR(SEARCH(M$1,$L12)),"","○") | N12: =IF(ISERROR(SEARCH(N$1,$L12)),"","○") | O12: =IF(ISERROR(SEARCH(O$1,$L12)),"","○") | P12: =IF(ISERROR(SEARCH(P$1,$L12)),"","○") | Q12: =IF(ISERROR(SEARCH(Q$1,$L12)),"","○") | R12: =IF(ISERROR(SEARCH(R$1,$L12)),"","○") | T12: 家庭でふれあいや体験活動等に取り組みたい | U12: 11月22日以外 | V12: 11月23日には、全国の神社で新嘗祭が行われ、連休を活かして活動しようとすると、地域の行事とバッティングする。 この度、同様の取り組みが他県でも実施されていることを知らず、県外旅行を計画したが、平日にもかかわらず旅行先が混雑しており、拍子抜けした。他市、他県での取り組み状況について情報提供いただけるとありがたい。
A13: 45632.963 | B13: 未就学児, 小学校１年生, 小学校３年生 | C13: =IF(ISERROR(FIND(C$1,$B13)),"×","○") -> ○ | D13: =IF(ISERROR(FIND(D$1,$B13)),"×","○") -> ○ | E13: =IF(ISERROR(FIND(E$1,$B13)),"×","○") -> × | F13: =IF(ISERROR(FIND(F$1,$B13)),"×","○") -> × | G13: 過ごしていない | J13: （回答者様以外の）家族、親類等と過ごした | K13: 取得していない | L13: 取得しにくかった | M13: =IF(ISERROR(SEARCH(M$1,$L13)),"","○") | N13: =IF(ISERROR(SEARCH(N$1,$L13)),"","○") | O13: =IF(ISERROR(SEARCH(O$1,$L13)),"","○") | P13: =IF(ISERROR(SEARCH(P$1,$L13)),"","○") | Q13: =IF(ISERROR(SEARCH(Q$1,$L13)),"","○") -> ○ | R13: =IF(ISERROR(SEARCH(R$1,$L13)),"","○") | S13: 私は児童福祉施設で働いています。小学生の学童保育や中高生の学習支援などの仕事をしています。この日もお仕事をされていた親御さんがおられたので、利用児童の対応がありました。それもあり休みをとりにくかったです。 | T13: 体験等に取り組みたいが休暇が取得できるか分からない | U13: 11月ではなくても、どこかで。 | V13: 人様のお子様の面倒を見る職種の人間は休みがとれない。その人たちにも家庭があり子どもがいて、自分の子は学童に預けて人様のお子様を見るということになる。どうしようもないことだが。
A14: 45626.892 | B14: 小学校６年生 | C14: =IF(ISERROR(FIND(C$1,$B14)),"×","○") -> × | D14: =IF(ISERROR(FIND(D$1,$B14)),"×","○") -> ○ | E14: =IF(ISERROR(FIND(E$1,$B14)),"×","○") -> × | F14: =IF(ISERROR(FIND(F$1,$B14)),"×","○") -> × | G14: 過ごした | H14: 倉吉市外へ出かけた | I14: せっかくの休みだったので、県外にある水族館へ出かけました。 | K14: 取得した | M14: =IF(ISERROR(SEARCH(M$1,$L14)),"","○") | N14: =IF(ISERROR(SEARCH(N$1,$L14)),"","○") | O14: =IF(ISERROR(SEARCH(O$1,$L14)),"","○") | P14: =IF(ISERROR(SEARCH(P$1,$L14)),"","○") | Q14: =IF(ISERROR(SEARCH(Q$1,$L14)),"","○") | R14: =IF(ISERROR(SEARCH(R$1,$L14)),"","○") | T14: その時により考えたい | U14: 11月でも良いが、なんにもない時期がいい | V14: 金曜日にしてもらえたので、次の日も気楽にいれた。
A15: 45621.451 | B15: 未就学児, 小学校３年生 | C15: =IF(ISERROR(FIND(C$1,$B15)),"×","○") -> ○ | D15: =IF(ISERROR(FIND(D$1,$B15)),"×","○") -> ○ | E15: =IF(ISERROR(FIND(E$1,$B15)),"×","○") -> × | F15: =IF(ISERROR(FIND(F$1,$B15)),"×","○") -> × | G15: 過ごした | H15: イベント等に参加した | I15: 栞づくりに参加した | K15: 取得していない | L15: そもそも働いていない | M15: =IF(ISERROR(SEARCH(M$1,$L15)),"","○") | N15: =IF(ISERROR(SEARCH(N$1,$L15)),"","○") | O15: =IF(ISERROR(SEARCH(O$1,$L15)),"","○") | P15: =IF(ISERROR(SEARCH(P$1,$L15)),"","○") | Q15: =IF(ISERROR(SEARCH(Q$1,$L15)),"","○") | R15: =IF(ISERROR(SEARCH(R$1,$L15)),"","○") | U15: 11月の同じ時期
A16: 45621.456 | B16: 中学校１年生, 中学校２年生 | C16: =IF(ISERROR(FIND(C$1,$B16)),"×","○") -> × | D16: =IF(ISERROR(FIND(D$1,$B16)),"×","○") -> × | E16: =IF(ISERROR(FIND(E$1,$B16)),"×","○") -> ○ | F16: =IF(ISERROR(FIND(F$1,$B16)),"×","○") -> × | G16: 過ごした | H16: 倉吉市外へ出かけた | I16: お買い物 | K16: 取得していない | L16: 勤務日ではなかった | M16: =IF(ISERROR(SEARCH(M$1,$L16)),"","○") | N16: =IF(ISERROR(SEARCH(N$1,$L16)),"","○") | O16: =IF(ISERROR(SEARCH(O$1,$L16)),"","○") | P16: =IF(ISERROR(SEARCH(P$1,$L16)),"","○") | Q16: =IF(ISERROR(SEARCH(Q$1,$L16)),"","○") | R16: =IF(ISERROR(SEARCH(R$1,$L16)),"","○") -> ○ | T16: 体験等に取り組みたいが休暇が取得できるか分からない | U16: 11月の同じ時期
A17: 45621.462 | B17: 中学校２年生, 中学校卒業後 | C17: =IF(ISERROR(FIND(C$1,$B17)),"×","○") -> × | D17: =IF(ISERROR(FIND(D$1,$B17)),"×","○") -> × | E17: =IF(ISERROR(FIND(E$1,$B17)),"×","○") -> ○ | F17: =IF(ISERROR(FIND(F$1,$B17)),"×","○") -> ○ | G17: 過ごした | H17: その他 | I17: 病院受診など | K17: 取得した | M17: =IF(ISERROR(SEARCH(M$1,$L17)),"","○") | N17: =IF(ISERROR(SEARCH(N$1,$L17)),"","○") | O17: =IF(ISERROR(SEARCH(O$1,$L17)),"","○") | P17: =IF(ISERROR(SEARCH(P$1,$L17)),"","○") | Q17: =IF(ISERROR(SEARCH(Q$1,$L17)),"","○") | R17: =IF(ISERROR(SEARCH(R$1,$L17)),"","○") | T17: 体験等に取り組みたいが休暇が取得できるか分からない | U17: 11月の同じ時期
A18: 45621.473 | B18: 未就学児, 小学校１年生 | C18: =IF(ISERROR(FIND(C$1,$B18)),"×","○") -> ○ | D18: =IF(ISERROR(FIND(D$1,$B18)),"×","○") -> ○ | E18: =IF(ISERROR(FIND(E$1,$B18)),"×","○") -> × | F18: =IF(ISERROR(FIND(F$1,$B18)),"×","○") -> × | G18: 過ごしていない | J18: イベントに参加した | K18: 取得していない | L18: 取得するつもりはなかった | M18: =IF(ISERROR(SEARCH(M$1,$L18)),"","○") | N18: =IF(ISERROR(SEARCH(N$1,$L18)),"","○") | O18: =IF(ISERROR(SEARCH(O$1,$L18)),"","○") | P18: =IF(ISERROR(SEARCH(P$1,$L18)),"","○") -> ○ | Q18: =IF(ISERROR(SEARCH(Q$1,$L18)),"","○") | R18: =IF(ISERROR(SEARCH(R$1,$L18)),"","○") | S18: 母親がみた | T18: 体験等に取り組むつもりはない | U18: 11月の同じ時期
A19: 45622.743 | B19: 未就学児, 小学校４年生, 中学校３年生 | C19: =IF(ISERROR(FIND(C$1,$B19)),"×","○") -> ○ | D19: =IF(ISERROR(FIND(D$1,$B19)),"×","○") -> ○ | E19: =IF(ISERROR(FIND(E$1,$B19)),"×","○") -> ○ | F19: =IF(ISERROR(FIND(F$1,$B19)),"×","○") -> × | G19: 過ごした | H19: イベント等に参加した | I19: 徳田先生と遊んだ | K19: 取得した | M19: =IF(ISERROR(SEARCH(M$1,$L19)),"","○") | N19: =IF(ISERROR(SEARCH(N$1,$L19)),"","○") | O19: =IF(ISERROR(SEARCH(O$1,$L19)),"","○") | P19: =IF(ISERROR(SEARCH(P$1,$L19)),"","○") | Q19: =IF(ISERROR(SEARCH(Q$1,$L19)),"","○") | R19: =IF(ISERROR(SEARCH(R$1,$L19)),"","○") | T19: 家庭でふれあいや体験活動等に取り組みたい | U19: 11月の同じ時期 | V19: 佐藤さんお疲れ様
A20: 45624.724 | B20: 中学校１年生, 中学校３年生 | C20: =IF(ISERROR(FIND(C$1,$B20)),"×","○") -> × | D20: =IF(ISERROR(FIND(D$1,$B20)),"×","○") -> × | E20: =IF(ISERROR(FIND(E$1,$B20)),"×","○") -> ○ | F20: =IF(ISERROR(FIND(F$1,$B20)),"×","○") -> × | G20: 過ごした | H20: 倉吉市外へ出かけた | I20: 買い物 | K20: 取得していない | L20: 家に居るから | M20: =IF(ISERROR(SEARCH(M$1,$L20)),"","○") | N20: =IF(ISERROR(SEARCH(N$1,$L20)),"","○") | O20: =IF(ISERROR(SEARCH(O$1,$L20)),"","○") | P20: =IF(ISERROR(SEARCH(P$1,$L20)),"","○") | Q20: =IF(ISERROR(SEARCH(Q$1,$L20)),"","○") | R20: =IF(ISERROR(SEARCH(R$1,$L20)),"","○") | T20: 家庭でふれあいや体験活動等に取り組みたい | U20: 11月の同じ時期
A21: 45624.766 | B21: 中学校３年生 | C21: =IF(ISERROR(FIND(C$1,$B21)),"×","○") -> × | D21: =IF(ISERROR(FIND(D$1,$B21)),"×","○") -> × | E21: =IF(ISERROR(FIND(E$1,$B21)),"×","○") -> ○ | F21: =IF(ISERROR(FIND(F$1,$B21)),"×","○") -> × | G21: 過ごした | H21: 家庭で過ごした | I21: 家で一緒に過ごした。 | K21: 取得していない | L21: 取得しにくかった | M21: =IF(ISERROR(SEARCH(M$1,$L21)),"","○") | N21: =IF(ISERROR(SEARCH(N$1,$L21)),"","○") | O21: =IF(ISERROR(SEARCH(O$1,$L21)),"","○") | P21: =IF(ISERROR(SEARCH(P$1,$L21)),"","○") | Q21: =IF(ISERROR(SEARCH(Q$1,$L21)),"","○") -> ○ | R21: =IF(ISERROR(SEARCH(R$1,$L21)),"","○") | S21: 勤務表がでていたため | T21: 家庭でふれあいや体験活動等に取り組みたい | U21: 11月の同じ時期
A22: 45624.775 | B22: 未就学児, 小学校６年生, 中学校１年生, 中学校３年生 | C22: =IF(ISERROR(FIND(C$1,$B22)),"×","○") -> ○ | D22: =IF(ISERROR(FIND(D$1,$B22)),"×","○") -> ○ | E22: =IF(ISERROR(FIND(E$1,$B22)),"×","○") -> ○ | F22: =IF(ISERROR(FIND(F$1,$B22)),"×","○") -> × | G22: 過ごした | H22: 家庭で過ごした | I22: ゆっくり過ごした | K22: 取得した | M22: =IF(ISERROR(SEARCH(M$1,$L22)),"","○") | N22: =IF(ISERROR(SEARCH(N$1,$L22)),"","○") | O22: =IF(ISERROR(SEARCH(O$1,$L22)),"","○") | P22: =IF(ISERROR(SEARCH(P$1,$L22)),"","○") | Q22: =IF(ISERROR(SEARCH(Q$1,$L22)),"","○") | R22: =IF(ISERROR(SEARCH(R$1,$L22)),"","○") | T22: 体験等に取り組むつもりはない | U22: 11月の同じ時期
A23: 45624.829 | B23: 中学校２年生 | C23: =IF(ISERROR(FIND(C$1,$B23)),"×","○") -> × | D23: =IF(ISERROR(FIND(D$1,$B23)),"×","○") -> × | E23: =IF(ISERROR(FIND(E$1,$B23)),"×","○") -> ○ | F23: =IF(ISERROR(FIND(F$1,$B23)),"×","○") -> × | G23: 過ごしていない | J23: 子どもだけで過ごした | K23: 取得していない | L23: 業務多忙で取得できなかった | M23: =IF(ISERROR(SEARCH(M$1,$L23)),"","○") | N23: =IF(ISERROR(SEARCH(N$1,$L23)),"","○") -> ○ | O23: =IF(ISERROR(SEARCH(O$1,$L23)),"","○") | P23: =IF(ISERROR(SEARCH(P$1,$L23)),"","○") | Q23: =IF(ISERROR(SEARCH(Q$1,$L23)),"","○") | R23: =IF(ISERROR(SEARCH(R$1,$L23)),"","○") | T23: 体験等に取り組みたいが休暇が取得できるか分からない | U23: 11月の同じ時期
A24: 45624.863 | B24: 中学校１年生, 中学校卒業後 | C24: =IF(ISERROR(FIND(C$1,$B24)),"×","○") -> × | D24: =IF(ISERROR(FIND(D$1,$B24)),"×","○") -> × | E24: =IF(ISERROR(FIND(E$1,$B24)),"×","○") -> ○ | F24: =IF(ISERROR(FIND(F$1,$B24)),"×","○") -> ○ | G24: 過ごしていない | J24: 友達と遊んでいた | K24: 取得していない | L24: 取得するつもりはなかった | M24: =IF(ISERROR(SEARCH(M$1,$L24)),"","○") | N24: =IF(ISERROR(SEARCH(N$1,$L24)),"","○") | O24: =IF(ISERROR(SEARCH(O$1,$L24)),"","○") | P24: =IF(ISERROR(SEARCH(P$1,$L24)),"","○") -> ○ | Q24: =IF(ISERROR(SEARCH(Q$1,$L24)),"","○") | R24: =IF(ISERROR(SEARCH(R$1,$L24)),"","○") | S24: 職場のスタッフが不足してしまうから | T24: 体験等に取り組みたいが休暇が取得できるか分からない | U24: 11月の同じ時期 | V24: 中学生男子は親と過ごすなんてあり得ない
A25: 45625.004 | B25: 中学校３年生 | C25: =IF(ISERROR(FIND(C$1,$B25)),"×","○") -> × | D25: =IF(ISERROR(FIND(D$1,$B25)),"×","○") -> × | E25: =IF(ISERROR(FIND(E$1,$B25)),"×","○") -> ○ | F25: =IF(ISERROR(FIND(F$1,$B25)),"×","○") -> × | G25: 過ごしていない | J25: 子どもだけで過ごした | K25: 取得していない | L25: 自営業だから | M25: =IF(ISERROR(SEARCH(M$1,$L25)),"","○") | N25: =IF(ISERROR(SEARCH(N$1,$L25)),"","○") | O25: =IF(ISERROR(SEARCH(O$1,$L25)),"","○") -> ○ | P25: =IF(ISERROR(SEARCH(P$1,$L25)),"","○") | Q25: =IF(ISERROR(SEARCH(Q$1,$L25)),"","○") | R25: =IF(ISERROR(SEARCH(R$1,$L25)),"","○") | T25: イベント等で体験活動に参加したい | U25: 11月の同じ時期
A26: 45625.018 | B26: 小学校５年生, 中学校２年生 | C26: =IF(ISERROR(FIND(C$1,$B26)),"×","○") -> × | D26: =IF(ISERROR(FIND(D$1,$B26)),"×","○") -> ○ | E26: =IF(ISERROR(FIND(E$1,$B26)),"×","○") -> ○ | F26: =IF(ISERROR(FIND(F$1,$B26)),"×","○") -> × | G26: 過ごした | H26: 倉吉市外へ出かけた | I26: 出雲大社へ行きました。 | K26: 取得した | M26: =IF(ISERROR(SEARCH(M$1,$L26)),"","○") | N26: =IF(ISERROR(SEARCH(N$1,$L26)),"","○") | O26: =IF(ISERROR(SEARCH(O$1,$L26)),"","○") | P26: =IF(ISERROR(SEARCH(P$1,$L26)),"","○") | Q26: =IF(ISERROR(SEARCH(Q$1,$L26)),"","○") | R26: =IF(ISERROR(SEARCH(R$1,$L26)),"","○") | T26: 家庭でふれあいや体験活動等に取り組みたい | U26: 11月の同じ時期 | V26: 周りの人はふれあいホリデーだと知らなくて休みを取っていない保護者も結構ありました。 休みになっても友達と遊びに行っている子ども達も結構あったみたいで休みである必要があるのかどうか疑問です。 我が家は来年も休みになれば家族でどこかにお出かけしたいと思います。普段行かない所に平日行けたので、人も少なくて過ごしやすかったです。
A27: 45625.341 | B27: 小学校４年生, 中学校１年生 | C27: =IF(ISERROR(FIND(C$1,$B27)),"×","○") -> × | D27: =IF(ISERROR(FIND(D$1,$B27)),"×","○") -> ○ | E27: =IF(ISERROR(FIND(E$1,$B27)),"×","○") -> ○ | F27: =IF(ISERROR(FIND(F$1,$B27)),"×","○") -> × | G27: 過ごした | H27: 倉吉市内へ出かけた | I27: 食事と買い物 | K27: 取得した | M27: =IF(ISERROR(SEARCH(M$1,$L27)),"","○") | N27: =IF(ISERROR(SEARCH(N$1,$L27)),"","○") | O27: =IF(ISERROR(SEARCH(O$1,$L27)),"","○") | P27: =IF(ISERROR(SEARCH(P$1,$L27)),"","○") | Q27: =IF(ISERROR(SEARCH(Q$1,$L27)),"","○") | R27: =IF(ISERROR(SEARCH(R$1,$L27)),"","○") | T27: 体験等に取り組みたいが休暇が取得できるか分からない | U27: 11月の同じ時期 | V27: 特になし
A28: 45625.39 | B28: 中学校１年生 | C28: =IF(ISERROR(FIND(C$1,$B28)),"×","○") -> × | D28: =IF(ISERROR(FIND(D$1,$B28)),"×","○") -> × | E28: =IF(ISERROR(FIND(E$1,$B28)),"×","○") -> ○ | F28: =IF(ISERROR(FIND(F$1,$B28)),"×","○") -> × | G28: 過ごしていない | J28: 友だちと遊びに行きました | K28: 取得していない | L28: 自営業だから | M28: =IF(ISERROR(SEARCH(M$1,$L28)),"","○") | N28: =IF(ISERROR(SEARCH(N$1,$L28)),"","○") | O28: =IF(ISERROR(SEARCH(O$1,$L28)),"","○") -> ○ | P28: =IF(ISERROR(SEARCH(P$1,$L28)),"","○") | Q28: =IF(ISERROR(SEARCH(Q$1,$L28)),"","○") | R28: =IF(ISERROR(SEARCH(R$1,$L28)),"","○") | T28: 家族よりも友だちを優先すると思います | U28: 11月の同じ時期
A29: 45625.557 | B29: 中学校２年生 | C29: =IF(ISERROR(FIND(C$1,$B29)),"×","○") -> × | D29: =IF(ISERROR(FIND(D$1,$B29)),"×","○") -> × | E29: =IF(ISERROR(FIND(E$1,$B29)),"×","○") -> ○ | F29: =IF(ISERROR(FIND(F$1,$B29)),"×","○") -> × | G29: 過ごしていない | J29: 子どもだけで過ごした | K29: 取得していない | L29: 取得しにくかった | M29: =IF(ISERROR(SEARCH(M$1,$L29)),"","○") | N29: =IF(ISERROR(SEARCH(N$1,$L29)),"","○") | O29: =IF(ISERROR(SEARCH(O$1,$L29)),"","○") | P29: =IF(ISERROR(SEARCH(P$1,$L29)),"","○") | Q29: =IF(ISERROR(SEARCH(Q$1,$L29)),"","○") -> ○ | R29: =IF(ISERROR(SEARCH(R$1,$L29)),"","○") | S29: 土曜、日曜日と私用があり3連休は取得しにくかった。 | T29: 親が仕事でも、子供達だけで参加出来るイベントを開催してほしい。 | U29: 11月の同じ時期 | V29: 子供達だけで、朝からスーパーに買い物に来てた。 近くの公民館などで、気軽に子供だけで、参加出来るイベントを開催してもらえると、安心できる。
A30: 45625.565 | B30: 中学校３年生 | C30: =IF(ISERROR(FIND(C$1,$B30)),"×","○") -> × | D30: =IF(ISERROR(FIND(D$1,$B30)),"×","○") -> × | E30: =IF(ISERROR(FIND(E$1,$B30)),"×","○") -> ○ | F30: =IF(ISERROR(FIND(F$1,$B30)),"×","○") -> × | G30: 過ごした | H30: 倉吉市内へ出かけた | I30: 市内でお昼ごはんを食べたり、お買い物をしたりしました。久しぶりの平日のお休みだったので、ゆっくりと過ごすことが出来ました。 | K30: 取得していない | L30: 専業主婦 | M30: =IF(ISERROR(SEARCH(M$1,$L30)),"","○") | N30: =IF(ISERROR(SEARCH(N$1,$L30)),"","○") | O30: =IF(ISERROR(SEARCH(O$1,$L30)),"","○") | P30: =IF(ISERROR(SEARCH(P$1,$L30)),"","○") | Q30: =IF(ISERROR(SEARCH(Q$1,$L30)),"","○") | R30: =IF(ISERROR(SEARCH(R$1,$L30)),"","○") | T30: 家庭でふれあいや体験活動等に取り組みたい | U30: 11月の同じ時期 | V30: わが子と一緒に過ごす時間を大切にできる取り組みだと思います。こういった時間が少しずつ増えていったらなぁ…と感じました。
A31: 45625.63 | B31: 未就学児, 小学校１年生 | C31: =IF(ISERROR(FIND(C$1,$B31)),"×","○") -> ○ | D31: =IF(ISERROR(FIND(D$1,$B31)),"×","○") -> ○ | E31: =IF(ISERROR(FIND(E$1,$B31)),"×","○") -> × | F31: =IF(ISERROR(FIND(F$1,$B31)),"×","○") -> × | G31: 過ごした | H31: 家庭で過ごした | I31: 第二子(年中児)が体調不良で休みだったため自宅で過ごした。第一子(小1)と料理を作った。 | K31: 取得していない | L31: 育児休暇中 | M31: =IF(ISERROR(SEARCH(M$1,$L31)),"","○") | N31: =IF(ISERROR(SEARCH(N$1,$L31)),"","○") | O31: =IF(ISERROR(SEARCH(O$1,$L31)),"","○") | P31: =IF(ISERROR(SEARCH(P$1,$L31)),"","○") | Q31: =IF(ISERROR(SEARCH(Q$1,$L31)),"","○") | R31: =IF(ISERROR(SEARCH(R$1,$L31)),"","○") | T31: イベント等で体験活動に参加したい | U31: 11月の同じ時期 | V31: ふれあいホリデーがあってもなくても、ふれあいを大切にする家庭とそうでない家庭は分かれると思うので、わざわざこのような休日を持つのは不要かと思います。どうしても学童等に行かなければならない知人家族の話を聞くと可哀想だと感じました。
A32: 45625.637 | B32: 小学校２年生 | C32: =IF(ISERROR(FIND(C$1,$B32)),"×","○") -> × | D32: =IF(ISERROR(FIND(D$1,$B32)),"×","○") -> ○ | E32: =IF(ISERROR(FIND(E$1,$B32)),"×","○") -> × | F32: =IF(ISERROR(FIND(F$1,$B32)),"×","○") -> × | G32: 過ごした | H32: 倉吉市外へ出かけた | I32: 家族で旅行 | K32: 取得した | M32: =IF(ISERROR(SEARCH(M$1,$L32)),"","○") | N32: =IF(ISERROR(SEARCH(N$1,$L32)),"","○") | O32: =IF(ISERROR(SEARCH(O$1,$L32)),"","○") | P32: =IF(ISERROR(SEARCH(P$1,$L32)),"","○") | Q32: =IF(ISERROR(SEARCH(Q$1,$L32)),"","○") | R32: =IF(ISERROR(SEARCH(R$1,$L32)),"","○") | T32: 家庭でふれあいや体験活動等に取り組みたい | U32: 11月の同じ時期 | V32: 早くから日程等告知があったので飛行機や宿泊先の予約、旅の計画が出来て良かった。
A33: 45625.644 | B33: 小学校３年生 | C33: =IF(ISERROR(FIND(C$1,$B33)),"×","○") -> × | D33: =IF(ISERROR(FIND(D$1,$B33)),"×","○") -> ○ | E33: =IF(ISERROR(FIND(E$1,$B33)),"×","○") -> × | F33: =IF(ISERROR(FIND(F$1,$B33)),"×","○") -> × | G33: 過ごした | H33: イベント等に参加した | I33: チラシに載っている博物館のイベントに参加しました | K33: 取得していない | L33: 勤務日ではなかった | M33: =IF(ISERROR(SEARCH(M$1,$L33)),"","○") | N33: =IF(ISERROR(SEARCH(N$1,$L33)),"","○") | O33: =IF(ISERROR(SEARCH(O$1,$L33)),"","○") | P33: =IF(ISERROR(SEARCH(P$1,$L33)),"","○") | Q33: =IF(ISERROR(SEARCH(Q$1,$L33)),"","○") | R33: =IF(ISERROR(SEARCH(R$1,$L33)),"","○") -> ○ | T33: イベント等で体験活動に参加したい | U33: 11月の同じ時期 | V33: 普段から土日に市内の色々なイベントに参加しているので、イベントの内容的には特別な日だとは感じませんでしたが、平日休みは新鮮で良かったです。3連休になったのも嬉しいです
A34: 45625.645 | B34: 小学校２年生 | C34: =IF(ISERROR(FIND(C$1,$B34)),"×","○") -> × | D34: =IF(ISERROR(FIND(D$1,$B34)),"×","○") -> ○ | E34: =IF(ISERROR(FIND(E$1,$B34)),"×","○") -> × | F34: =IF(ISERROR(FIND(F$1,$B34)),"×","○") -> × | G34: 過ごした | H34: 倉吉市外へ出かけた | I34: ジョイフルパークに遊びに行きました。 | K34: 取得していない | L34: 勤務日ではなかった | M34: =IF(ISERROR(SEARCH(M$1,$L34)),"","○") | N34: =IF(ISERROR(SEARCH(N$1,$L34)),"","○") | O34: =IF(ISERROR(SEARCH(O$1,$L34)),"","○") | P34: =IF(ISERROR(SEARCH(P$1,$L34)),"","○") | Q34: =IF(ISERROR(SEARCH(Q$1,$L34)),"","○") | R34: =IF(ISERROR(SEARCH(R$1,$L34)),"","○") -> ○ | T34: イベント等で体験活動に参加したい | U34: 11月の同じ時期 | V34: 親が休めないとあまり意味がないなと思いました。今回は母親のみ休めていたので有意義に過ごせました。
A35: 45625.65 | B35: 中学校２年生 | C35: =IF(ISERROR(FIND(C$1,$B35)),"×","○") -> × | D35: =IF(ISERROR(FIND(D$1,$B35)),"×","○") -> × | E35: =IF(ISERROR(FIND(E$1,$B35)),"×","○") -> ○ | F35: =IF(ISERROR(FIND(F$1,$B35)),"×","○") -> × | G35: 過ごしていない | J35: 子どもだけで過ごした | K35: 取得していない | L35: 取得するつもりはなかった | M35: =IF(ISERROR(SEARCH(M$1,$L35)),"","○") | N35: =IF(ISERROR(SEARCH(N$1,$L35)),"","○") | O35: =IF(ISERROR(SEARCH(O$1,$L35)),"","○") | P35: =IF(ISERROR(SEARCH(P$1,$L35)),"","○") -> ○ | Q35: =IF(ISERROR(SEARCH(Q$1,$L35)),"","○") | R35: =IF(ISERROR(SEARCH(R$1,$L35)),"","○") | S35: シフトが休みなら休めばいいと思った。出かけるなら家族揃って休みの日に出かけたい。 | T35: イベントの情報があれば考える | U35: 11月の同じ時期
A36: 45625.651 | B36: 未就学児, 小学校１年生 | C36: =IF(ISERROR(FIND(C$1,$B36)),"×","○") -> ○ | D36: =IF(ISERROR(FIND(D$1,$B36)),"×","○") -> ○ | E36: =IF(ISERROR(FIND(E$1,$B36)),"×","○") -> × | F36: =IF(ISERROR(FIND(F$1,$B36)),"×","○") -> × | G36: 過ごした | H36: 倉吉市外へ出かけた | I36: 朝からショッピングモールに行った | K36: 取得した | M36: =IF(ISERROR(SEARCH(M$1,$L36)),"","○") | N36: =IF(ISERROR(SEARCH(N$1,$L36)),"","○") | O36: =IF(ISERROR(SEARCH(O$1,$L36)),"","○") | P36: =IF(ISERROR(SEARCH(P$1,$L36)),"","○") | Q36: =IF(ISERROR(SEARCH(Q$1,$L36)),"","○") | R36: =IF(ISERROR(SEARCH(R$1,$L36)),"","○") | T36: 遠出をする | U36: 11月の同じ時期
A37: 45625.665 | B37: 小学校３年生, 中学校１年生, 中学校３年生 | C37: =IF(ISERROR(FIND(C$1,$B37)),"×","○") -> × | D37: =IF(ISERROR(FIND(D$1,$B37)),"×","○") -> ○ | E37: =IF(ISERROR(FIND(E$1,$B37)),"×","○") -> ○ | F37: =IF(ISERROR(FIND(F$1,$B37)),"×","○") -> × | G37: 過ごしていない | J37: 知り合いに預けた | K37: 取得していない | L37: 取得しにくかった | M37: =IF(ISERROR(SEARCH(M$1,$L37)),"","○") | N37: =IF(ISERROR(SEARCH(N$1,$L37)),"","○") | O37: =IF(ISERROR(SEARCH(O$1,$L37)),"","○") | P37: =IF(ISERROR(SEARCH(P$1,$L37)),"","○") | Q37: =IF(ISERROR(SEARCH(Q$1,$L37)),"","○") -> ○ | R37: =IF(ISERROR(SEARCH(R$1,$L37)),"","○") | S37: 学校行事で有給を使っており、休みにくい | T37: 体験等に取り組みたいが休暇が取得できるか分からない | U37: 11月の同じ時期
A38: 45625.693 | B38: 小学校３年生, 小学校６年生 | C38: =IF(ISERROR(FIND(C$1,$B38)),"×","○") -> × | D38: =IF(ISERROR(FIND(D$1,$B38)),"×","○") -> ○ | E38: =IF(ISERROR(FIND(E$1,$B38)),"×","○") -> × | F38: =IF(ISERROR(FIND(F$1,$B38)),"×","○") -> × | G38: 過ごしていない | J38: （回答者様以外の）家族、親類等と過ごした | K38: 取得していない | L38: 取得しにくかった | M38: =IF(ISERROR(SEARCH(M$1,$L38)),"","○") | N38: =IF(ISERROR(SEARCH(N$1,$L38)),"","○") | O38: =IF(ISERROR(SEARCH(O$1,$L38)),"","○") | P38: =IF(ISERROR(SEARCH(P$1,$L38)),"","○") | Q38: =IF(ISERROR(SEARCH(Q$1,$L38)),"","○") -> ○ | R38: =IF(ISERROR(SEARCH(R$1,$L38)),"","○") | S38: 金曜日休むと3連休になるため休めない | T38: 体験等に取り組みたいが休暇が取得できるか分からない | U38: 11月の同じ時期 | V38: 仕事の休みがとりづらい。
A39: 45625.709 | B39: 未就学児, 小学校３年生, 小学校５年生 | C39: =IF(ISERROR(FIND(C$1,$B39)),"×","○") -> ○ | D39: =IF(ISERROR(FIND(D$1,$B39)),"×","○") -> ○ | E39: =IF(ISERROR(FIND(E$1,$B39)),"×","○") -> × | F39: =IF(ISERROR(FIND(F$1,$B39)),"×","○") -> × | G39: 過ごしていない | J39: 学校の友達と遊んでいた | K39: 取得していない | L39: 取り組みを知らずに通常通りの仕事だった | M39: =IF(ISERROR(SEARCH(M$1,$L39)),"","○") | N39: =IF(ISERROR(SEARCH(N$1,$L39)),"","○") | O39: =IF(ISERROR(SEARCH(O$1,$L39)),"","○") | P39: =IF(ISERROR(SEARCH(P$1,$L39)),"","○") | Q39: =IF(ISERROR(SEARCH(Q$1,$L39)),"","○") | R39: =IF(ISERROR(SEARCH(R$1,$L39)),"","○") | T39: 前月にお知らせが欲しい | U39: 11月の同じ時期
A40: 45625.712 | B40: 小学校１年生, 小学校４年生, 中学校１年生 | C40: =IF(ISERROR(FIND(C$1,$B40)),"×","○") -> × | D40: =IF(ISERROR(FIND(D$1,$B40)),"×","○") -> ○ | E40: =IF(ISERROR(FIND(E$1,$B40)),"×","○") -> ○ | F40: =IF(ISERROR(FIND(F$1,$B40)),"×","○") -> × | G40: 過ごしていない | J40: 子どもだけで過ごした | K40: 取得していない | L40: 取得するつもりはなかった | M40: =IF(ISERROR(SEARCH(M$1,$L40)),"","○") | N40: =IF(ISERROR(SEARCH(N$1,$L40)),"","○") | O40: =IF(ISERROR(SEARCH(O$1,$L40)),"","○") | P40: =IF(ISERROR(SEARCH(P$1,$L40)),"","○") -> ○ | Q40: =IF(ISERROR(SEARCH(Q$1,$L40)),"","○") | R40: =IF(ISERROR(SEARCH(R$1,$L40)),"","○") | S40: 平日は仕事の為 | T40: 体験等に取り組みたいが休暇が取得できるか分からない | U40: 11月の同じ時期
...

Sheet Sheet1
B1: 保護者
B2: 問２ 11月22日（ふれあいホリデー）はお子様と一緒に過ごされましたか。
C3: 過ごした | D3: 過ごしていない | E3: 合計
B4: 小学校にいて、中学校にはいない | C4: =COUNTIFS(Form_Responses1[小学校],"○",Form_Responses1[中学校],"×",Form_Responses1[問２ 11月22日（ふれあいホリデー）はお子様と一緒に過ごされましたか。],C$3) -> 323 | D4: =COUNTIFS(Form_Responses1[小学校],"○",Form_Responses1[中学校],"×",Form_Responses1[問２ 11月22日（ふれあいホリデー）はお子様と一緒に過ごされましたか。],D$3) -> 299 | E4: =SUM(C4:D4) -> 622
B5: 小学校にはいなくて、中学校にいる | C5: =COUNTIFS(Form_Responses1[小学校],"×",Form_Responses1[中学校],"○",Form_Responses1[問２ 11月22日（ふれあいホリデー）はお子様と一緒に過ごされましたか。],C$3) -> 96 | D5: =COUNTIFS(Form_Responses1[小学校],"×",Form_Responses1[中学校],"○",Form_Responses1[問２ 11月22日（ふれあいホリデー）はお子様と一緒に過ごされましたか。],D$3) -> 157 | E5: =SUM(C5:D5) -> 253
B6: 未就学児がいる | C6: =COUNTIFS(Form_Responses1[未就学],"○",Form_Responses1[問２ 11月22日（ふれあいホリデー）はお子様と一緒に過ごされましたか。],C$3) -> 67 | D6: =COUNTIFS(Form_Responses1[未就学],"○",Form_Responses1[問２ 11月22日（ふれあいホリデー）はお子様と一緒に過ごされましたか。],D$3) -> 44 | E6: =SUM(C6:D6) -> 111
B7: 卒業した子がいる | C7: =COUNTIFS(Form_Responses1[卒業],"○",Form_Responses1[問２ 11月22日（ふれあいホリデー）はお子様と一緒に過ごされましたか。],C$3) -> 27 | D7: =COUNTIFS(Form_Responses1[卒業],"○",Form_Responses1[問２ 11月22日（ふれあいホリデー）はお子様と一緒に過ごされましたか。],D$3) -> 33 | E7: =SUM(C7:D7) -> 60
B8: 全体 | C8: =SUM(C4:C7) -> 513 | D8: =SUM(D4:D7) -> 533 | E8: =SUM(C8:D8) -> 1046
B9: 小学校にいて、中学校にはいない | C9: =C4/$E4 -> 0.5192926 | D9: =D4/$E4 -> 0.4807074
B10: 小学校にはいなくて、中学校にいる | C10: =C5/$E5 -> 0.37944664 | D10: =D5/$E5 -> 0.62055336
B11: 未就学児がいる | C11: =C6/$E6 -> 0.6036036 | D11: =D6/$E6 -> 0.3963964
B12: 卒業した子がいる | C12: =C7/$E7 -> 0.45 | D12: =D7/$E7 -> 0.55
B13: 全体 | C13: =C8/$E8 -> 0.49043977 | D13: =D8/$E8 -> 0.50956023
B16: 問３−Ａ１ 主にどのように過ごされましたか。
C17: 家庭で過ごした | D17: イベント等に参加した | E17: 倉吉市内へ出かけた | F17: 倉吉市外へ出かけた | G17: その他 | H17: 合計
B18: 全体 | C18: =SUM(C19:C22) -> 142 | D18: =SUM(D19:D22) -> 55 | E18: =SUM(E19:E22) -> 83 | F18: =SUM(F19:F22) -> 215 | G18: =SUM(G19:G22) -> 18 | H18: =SUM(C18:G18) -> 513
B19: 小学校にいて、中学校にはいない | C19: =COUNTIFS(フォームの回答!$D$2:$D$1088,"○",フォームの回答!$E$2:$E$1088,"×",フォームの回答!$G$2:$G$1088,"過ごした",フォームの回答!$H$2:$H$1088,C$17) -> 74 | D19: =COUNTIFS(フォームの回答!$D$2:$D$1088,"○",フォームの回答!$E$2:$E$1088,"×",フォームの回答!$G$2:$G$1088,"過ごした",フォームの回答!$H$2:$H$1088,D$17) -> 35 | E19: =COUNTIFS(フォームの回答!$D$2:$D$1088,"○",フォームの回答!$E$2:$E$1088,"×",フォームの回答!$G$2:$G$1088,"過ごした",フォームの回答!$H$2:$H$1088,E$17) -> 59 | F19: =COUNTIFS(フォームの回答!$D$2:$D$1088,"○",フォームの回答!$E$2:$E$1088,"×",フォームの回答!$G$2:$G$1088,"過ごした",フォームの回答!$H$2:$H$1088,F$17) -> 147 | G19: =COUNTIFS(フォームの回答!$D$2:$D$1088,"○",フォームの回答!$E$2:$E$1088,"×",フォームの回答!$G$2:$G$1088,"過ごした",フォームの回答!$H$2:$H$1088,G$17) -> 8 | H19: =SUM(C19:G19) -> 323
B20: 小学校にはいなくて、中学校にいる | C20: =COUNTIFS(フォームの回答!$D$2:$D$1088,"×",フォームの回答!$E$2:$E$1088,"○",フォームの回答!$G$2:$G$1088,"過ごした",フォームの回答!$H$2:$H$1088,C$17) -> 39 | D20: =COUNTIFS(フォームの回答!$D$2:$D$1088,"×",フォームの回答!$E$2:$E$1088,"○",フォームの回答!$G$2:$G$1088,"過ごした",フォームの回答!$H$2:$H$1088,D$17) -> 10 | E20: =COUNTIFS(フォームの回答!$D$2:$D$1088,"×",フォームの回答!$E$2:$E$1088,"○",フォームの回答!$G$2:$G$1088,"過ごした",フォームの回答!$H$2:$H$1088,E$17) -> 11 | F20: =COUNTIFS(フォームの回答!$D$2:$D$1088,"×",フォームの回答!$E$2:$E$1088,"○",フォームの回答!$G$2:$G$1088,"過ごした",フォームの回答!$H$2:$H$1088,F$17) -> 28 | G20: =COUNTIFS(フォームの回答!$D$2:$D$1088,"×",フォームの回答!$E$2:$E$1088,"○",フォームの回答!$G$2:$G$1088,"過ごした",フォームの回答!$H$2:$H$1088,G$17) -> 8 | H20: =SUM(C20:G20) -> 96
B21: 未就学児がいる | C21: =COUNTIFS(フォームの回答!$C$2:$C$1088,"○",フォームの回答!$G$2:$G$1088,"過ごした",フォームの回答!$H$2:$H$1088,C$17) -> 18 | D21: =COUNTIFS(フォームの回答!$C$2:$C$1088,"○",フォームの回答!$G$2:$G$1088,"過ごした",フォームの回答!$H$2:$H$1088,D$17) -> 8 | E21: =COUNTIFS(フォームの回答!$C$2:$C$1088,"○",フォームの回答!$G$2:$G$1088,"過ごした",フォームの回答!$H$2:$H$1088,E$17) -> 10 | F21: =COUNTIFS(フォームの回答!$C$2:$C$1088,"○",フォームの回答!$G$2:$G$1088,"過ごした",フォームの回答!$H$2:$H$1088,F$17) -> 31 | G21: =COUNTIFS(フォームの回答!$C$2:$C$1088,"○",フォームの回答!$G$2:$G$1088,"過ごした",フォームの回答!$H$2:$H$1088,G$17) -> 0 | H21: =SUM(C21:G21) -> 67
B22: 卒業した子がいる | C22: =COUNTIFS(フォームの回答!$F$2:$F$1088,"○",フォームの回答!$G$2:$G$1088,"過ごした",フォームの回答!$H$2:$H$1088,C$17) -> 11 | D22: =COUNTIFS(フォームの回答!$F$2:$F$1088,"○",フォームの回答!$G$2:$G$1088,"過ごした",フォームの回答!$H$2:$H$1088,D$17) -> 2 | E22: =COUNTIFS(フォームの回答!$F$2:$F$1088,"○",フォームの回答!$G$2:$G$1088,"過ごした",フォームの回答!$H$2:$H$1088,E$17) -> 3 | F22: =COUNTIFS(フォームの回答!$F$2:$F$1088,"○",フォームの回答!$G$2:$G$1088,"過ごした",フォームの回答!$H$2:$H$1088,F$17) -> 9 | G22: =COUNTIFS(フォームの回答!$F$2:$F$1088,"○",フォームの回答!$G$2:$G$1088,"過ごした",フォームの回答!$H$2:$H$1088,G$17) -> 2 | H22: =SUM(C22:G22) -> 27
B23: 小学校にいて、中学校にはいない | C23: =C19/$H19 -> 0.22910217 | D23: =D19/$H19 -> 0.10835913 | E23: =E19/$H19 -> 0.18266254 | F23: =F19/$H19 -> 0.45510836 | G23: =G19/$H19 -> 0.024767802
B24: 小学校にはいなくて、中学校にいる | C24: =C20/$H20 -> 0.40625 | D24: =D20/$H20 -> 0.10416667 | E24: =E20/$H20 -> 0.11458333 | F24: =F20/$H20 -> 0.29166667 | G24: =G20/$H20 -> 0.083333333
B25: 未就学児がいる | C25: =C21/$H21 -> 0.26865672 | D25: =D21/$H21 -> 0.11940299 | E25: =E21/$H21 -> 0.14925373 | F25: =F21/$H21 -> 0.46268657 | G25: =G21/$H21 -> 0
B26: 卒業した子がいる | C26: =C22/$H22 -> 0.40740741 | D26: =D22/$H22 -> 0.074074074 | E26: =E22/$H22 -> 0.11111111 | F26: =F22/$H22 -> 0.33333333 | G26: =G22/$H22 -> 0.074074074
B27: 全体 | C27: =C18/$H18 -> 0.27680312 | D27: =D18/$H18 -> 0.10721248 | E27: =E18/$H18 -> 0.16179337 | F27: =F18/$H18 -> 0.41910331 | G27: =G18/$H18 -> 0.035087719
B29: 問３−Ｂ１ お子様はどのように過ごされましたか。
C30: 放課後児童クラブ等を利用した | D30: （回答者様以外の）家族、親類等と過ごした | E30: 知り合いに預けた | F30: 子どもだけで過ごした | G30: その他 | H30: 合計
B31: 全体 | C31: =SUM(C32:C35) -> 117 | D31: =SUM(D32:D35) -> 116 | E31: =SUM(E32:E35) -> 12 | F31: =SUM(F32:F35) -> 230 | G31: =SUM(G32:G35) -> 58 | H31: =SUM(C31:G31) -> 533
B32: 小学校にいて、中学校にはいない | C32: =COUNTIFS(フォームの回答!$D$2:$D$1088,"○",フォームの回答!$E$2:$E$1088,"×",フォームの回答!$G$2:$G$1088,"過ごしていない",フォームの回答!$J$2:$J$1088,C$30) -> 98 | D32: =COUNTIFS(フォームの回答!$D$2:$D$1088,"○",フォームの回答!$E$2:$E$1088,"×",フォームの回答!$G$2:$G$1088,"過ごしていない",フォームの回答!$J$2:$J$1088,D$30) -> 80 | E32: =COUNTIFS(フォームの回答!$D$2:$D$1088,"○",フォームの回答!$E$2:$E$1088,"×",フォームの回答!$G$2:$G$1088,"過ごしていない",フォームの回答!$J$2:$J$1088,E$30) -> 8 | F32: =COUNTIFS(フォームの回答!$D$2:$D$1088,"○",フォームの回答!$E$2:$E$1088,"×",フォームの回答!$G$2:$G$1088,"過ごしていない",フォームの回答!$J$2:$J$1088,F$30) -> 92 | G32: =H32-SUM(C32:F32) -> 21 | H32: =D4 -> 299
B33: 小学校にはいなくて、中学校にいる | C33: =COUNTIFS(フォームの回答!$D$2:$D$1088,"×",フォームの回答!$E$2:$E$1088,"○",フォームの回答!$G$2:$G$1088,"過ごしていない",フォームの回答!$J$2:$J$1088,C$30) -> 0 | D33: =COUNTIFS(フォームの回答!$D$2:$D$1088,"×",フォームの回答!$E$2:$E$1088,"○",フォームの回答!$G$2:$G$1088,"過ごしていない",フォームの回答!$J$2:$J$1088,D$30) -> 22 | E33: =COUNTIFS(フォームの回答!$D$2:$D$1088,"×",フォームの回答!$E$2:$E$1088,"○",フォームの回答!$G$2:$G$1088,"過ごしていない",フォームの回答!$J$2:$J$1088,E$30) -> 1 | F33: =COUNTIFS(フォームの回答!$D$2:$D$1088,"×",フォームの回答!$E$2:$E$1088,"○",フォームの回答!$G$2:$G$1088,"過ごしていない",フォームの回答!$J$2:$J$1088,F$30) -> 106 | G33: =H33-SUM(C33:F33) -> 28 | H33: =D5 -> 157
B34: 未就学児がいる | C34: =COUNTIFS(フォームの回答!$C$2:$C$1088,"○",フォームの回答!$G$2:$G$1088,"過ごしていない",フォームの回答!$J$2:$J$1088,C$30) -> 16 | D34: =COUNTIFS(フォームの回答!$C$2:$C$1088,"○",フォームの回答!$G$2:$G$1088,"過ごしていない",フォームの回答!$J$2:$J$1088,D$30) -> 8 | E34: =COUNTIFS(フォームの回答!$C$2:$C$1088,"○",フォームの回答!$G$2:$G$1088,"過ごしていない",フォームの回答!$J$2:$J$1088,E$30) -> 2 | F34: =COUNTIFS(フォームの回答!$C$2:$C$1088,"○",フォームの回答!$G$2:$G$1088,"過ごしていない",フォームの回答!$J$2:$J$1088,F$30) -> 13 | G34: =H34-SUM(C34:F34) -> 5 | H34: =D6 -> 44
B35: 卒業した子がいる | C35: =COUNTIFS(フォームの回答!$F$2:$F$1088,"○",フォームの回答!$G$2:$G$1088,"過ごしていない",フォームの回答!$J$2:$J$1088,C$30) -> 3 | D35: =COUNTIFS(フォームの回答!$F$2:$F$1088,"○",フォームの回答!$G$2:$G$1088,"過ごしていない",フォームの回答!$J$2:$J$1088,D$30) -> 6 | E35: =COUNTIFS(フォームの回答!$F$2:$F$1088,"○",フォームの回答!$G$2:$G$1088,"過ごしていない",フォームの回答!$J$2:$J$1088,E$30) -> 1 | F35: =COUNTIFS(フォームの回答!$F$2:$F$1088,"○",フォームの回答!$G$2:$G$1088,"過ごしていない",フォームの回答!$J$2:$J$1088,F$30) -> 19 | G35: =H35-SUM(C35:F35) -> 4 | H35: =D7 -> 33
B36: 小学校にいて、中学校にはいない | C36: =C32/$H32 -> 0.3277592 | D36: =D32/$H32 -> 0.26755853 | E36: =E32/$H32 -> 0.026755853 | F36: =F32/$H32 -> 0.30769231 | G36: =G32/$H32 -> 0.070234114
B37: 小学校にはいなくて、中学校にいる | C37: =C33/$H33 -> 0 | D37: =D33/$H33 -> 0.14012739 | E37: =E33/$H33 -> 0.0063694268 | F37: =F33/$H33 -> 0.67515924 | G37: =G33/$H33 -> 0.17834395
B38: 未就学児がいる | C38: =C34/$H34 -> 0.36363636 | D38: =D34/$H34 -> 0.18181818 | E38: =E34/$H34 -> 0.045454545 | F38: =F34/$H34 -> 0.29545455 | G38: =G34/$H34 -> 0.11363636
B39: 卒業した子がいる | C39: =C35/$H35 -> 0.090909091 | D39: =D35/$H35 -> 0.18181818 | E39: =E35/$H35 -> 0.03030303 | F39: =F35/$H35 -> 0.57575758 | G39: =G35/$H35 -> 0.12121212
B40: 全体 | C40: =C31/$H31 -> 0.2195122 | D40: =D31/$H31 -> 0.21763602 | E40: =E31/$H31 -> 0.022514071 | F40: =F31/$H31 -> 0.4315197 | G40: =G31/$H31 -> 0.10881801
B42: 問４ あなたは休暇を取得されましたか
C43: 取得した | D43: 取得していない | E43: 合計 | F43: 取得した | G43: 取得していない
B44: 全体 | C44: =SUM(C45:C48) -> 394 | D44: =SUM(D45:D48) -> 652 | E44: =SUM(C44:D44) -> 1046 | F44: =C44/$E44 -> 0.37667304 | G44: =D44/$E44 -> 0.62332696
...

Sheet 整えたの
D3: 【保護者】
D5: 11月22日（ふれあいホリデー）はお子様と一緒に過ごされましたか。
D6: № | E6: 家庭のケース | F6: 実数 | I6: 率
F7: 合計 | G7: 過ごした | H7: 過ごしていない | I7: 過ごした | J7: 過ごしていない
D8: 1 | E8: 全体 | F8: =G8+H8 -> 1046 | G8: 513 | H8: 533 | I8: =G8/$F8 -> 0.49043977 | J8: =H8/$F8 -> 0.50956023
D9: 2 | E9: 小学生がいて、中学生はいない家庭 | F9: =G9+H9 -> 622 | G9: 323 | H9: 299 | I9: =G9/$F9 -> 0.5192926 | J9: =H9/$F9 -> 0.4807074
D10: 3 | E10: 小学生はいなくて、中学生がいる家庭 | F10: =G10+H10 -> 253 | G10: 96 | H10: 157 | I10: =G10/$F10 -> 0.37944664 | J10: =H10/$F10 -> 0.62055336
D11: 4 | E11: 未就学児がいる家庭 | F11: =G11+H11 -> 111 | G11: 67 | H11: 44 | I11: =G11/$F11 -> 0.6036036 | J11: =H11/$F11 -> 0.3963964
D12: 5 | E12: 中学校を卒業した子（高校生等）がいる家庭 | F12: =G12+H12 -> 60 | G12: 27 | H12: 33 | I12: =G12/$F12 -> 0.45 | J12: =H12/$F12 -> 0.55
D34: （「お子様と一緒に過ごした」と回答された方）主にどのように過ごされましたか。
D35: № | E35: 家庭のケース | F35: 家庭で過ごした | G35: イベント等に参加した | H35: 倉吉市内へ出かけた | I35: 倉吉市外へ出かけた | J35: その他 | K35: 合計
D36: 1 | E36: 全体 | F36: 142 | G36: 55 | H36: 83 | I36: 215 | J36: 18 | K36: =SUM(F36:J36) -> 513
D37: 2 | E37: 小学生がいて、中学生はいない家庭 | F37: 74 | G37: 35 | H37: 59 | I37: 147 | J37: 8 | K37: =SUM(F37:J37) -> 323
D38: 3 | E38: 小学生はいなくて、中学生がいる家庭 | F38: 39 | G38: 10 | H38: 11 | I38: 28 | J38: 8 | K38: =SUM(F38:J38) -> 96
D39: 4 | E39: 未就学児がいる家庭 | F39: 18 | G39: 8 | H39: 10 | I39: 31 | J39: 0 | K39: =SUM(F39:J39) -> 67
D40: 5 | E40: 中学校を卒業した子（高校生等）がいる家庭 | F40: 11 | G40: 2 | H40: 3 | I40: 9 | J40: 2 | K40: =SUM(F40:J40) -> 27
D42: 率 | E42: 全体 | F42: =F36/$K36 -> 0.27680312 | G42: =G36/$K36 -> 0.10721248 | H42: =H36/$K36 -> 0.16179337 | I42: =I36/$K36 -> 0.41910331 | J42: =J36/$K36 -> 0.035087719
E43: 小学生がいて、中学生はいない家庭 | F43: =F37/$K37 -> 0.22910217 | G43: =G37/$K37 -> 0.10835913 | H43: =H37/$K37 -> 0.18266254 | I43: =I37/$K37 -> 0.45510836 | J43: =J37/$K37 -> 0.024767802
E44: 小学生はいなくて、中学生がいる家庭 | F44: =F38/$K38 -> 0.40625 | G44: =G38/$K38 -> 0.10416667 | H44: =H38/$K38 -> 0.11458333 | I44: =I38/$K38 -> 0.29166667 | J44: =J38/$K38 -> 0.083333333
E45: 未就学児がいる家庭 | F45: =F39/$K39 -> 0.26865672 | G45: =G39/$K39 -> 0.11940299 | H45: =H39/$K39 -> 0.14925373 | I45: =I39/$K39 -> 0.46268657 | J45: =J39/$K39 -> 0
E46: 中学校を卒業した子（高校生等）がいる家庭 | F46: =F40/$K40 -> 0.40740741 | G46: =G40/$K40 -> 0.074074074 | H46: =H40/$K40 -> 0.11111111 | I46: =I40/$K40 -> 0.33333333 | J46: =J40/$K40 -> 0.074074074
D48: （「お子様と一緒に過ごしていない」と回答された方）お子様はどのように過ごされましたか。
D49: № | E49: 家庭のケース | F49: 放課後児童クラブ等を利用した | G49: （回答者様以外の）家族、親類等と過ごした | H49: 知り合いに預けた | I49: 子どもだけで過ごした | J49: その他 | K49: 合計
D50: 1 | E50: 全体 | F50: 117 | G50: 116 | H50: 12 | I50: 230 | J50: 58 | K50: =SUM(F50:J50) -> 533
D51: 2 | E51: 小学生がいて、中学生はいない家庭 | F51: 98 | G51: 80 | H51: 8 | I51: 92 | J51: 21 | K51: =SUM(F51:J51) -> 299
D52: 3 | E52: 小学生はいなくて、中学生がいる家庭 | F52: 0 | G52: 22 | H52: 1 | I52: 106 | J52: 28 | K52: =SUM(F52:J52) -> 157
D53: 4 | E53: 未就学児がいる家庭 | F53: 16 | G53: 8 | H53: 2 | I53: 13 | J53: 5 | K53: =SUM(F53:J53) -> 44
D54: 5 | E54: 中学校を卒業した子（高校生等）がいる家庭 | F54: 3 | G54: 6 | H54: 1 | I54: 19 | J54: 4 | K54: =SUM(F54:J54) -> 33
D56: 率 | E56: 全体 | F56: =F50/$K50 -> 0.2195122 | G56: =G50/$K50 -> 0.21763602 | H56: =H50/$K50 -> 0.022514071 | I56: =I50/$K50 -> 0.4315197 | J56: =J50/$K50 -> 0.10881801
E57: 小学生がいて、中学生はいない家庭 | F57: =F51/$K51 -> 0.3277592 | G57: =G51/$K51 -> 0.26755853 | H57: =H51/$K51 -> 0.026755853 | I57: =I51/$K51 -> 0.30769231 | J57: =J51/$K51 -> 0.070234114
E58: 小学生はいなくて、中学生がいる家庭 | F58: =F52/$K52 -> 0 | G58: =G52/$K52 -> 0.14012739 | H58: =H52/$K52 -> 0.0063694268 | I58: =I52/$K52 -> 0.67515924 | J58: =J52/$K52 -> 0.17834395
E59: 未就学児がいる家庭 | F59: =F53/$K53 -> 0.36363636 | G59: =G53/$K53 -> 0.18181818 | H59: =H53/$K53 -> 0.045454545 | I59: =I53/$K53 -> 0.29545455 | J59: =J53/$K53 -> 0.11363636
E60: 中学校を卒業した子（高校生等）がいる家庭 | F60: =F54/$K54 -> 0.090909091 | G60: =G54/$K54 -> 0.18181818 | H60: =H54/$K54 -> 0.03030303 | I60: =I54/$K54 -> 0.57575758 | J60: =J54/$K54 -> 0.12121212
D66: 休暇を取得されましたか
D67: № | E67: 家庭のケース | F67: 実数 | I67: 率
F68: 合計 | G68: 取得した | H68: 取得していない | I68: 取得した | J68: 取得していない
D69: 1 | E69: 全体 | F69: =G69+H69 -> 1046 | G69: 394 | H69: 652 | I69: =G69/$F69 -> 0.37667304 | J69: =H69/$F69 -> 0.62332696
D70: 2 | E70: 小学生がいて、中学生はいない家庭 | F70: =G70+H70 -> 622 | G70: 258 | H70: 364 | I70: =G70/$F70 -> 0.414791 | J70: =H70/$F70 -> 0.585209
D71: 3 | E71: 小学生はいなくて、中学生がいる家庭 | F71: =G71+H71 -> 253 | G71: 68 | H71: 185 | I71: =G71/$F71 -> 0.2687747 | J71: =H71/$F71 -> 0.7312253
D72: 4 | E72: 未就学児がいる家庭 | F72: =G72+H72 -> 111 | G72: 50 | H72: 61 | I72: =G72/$F72 -> 0.45045045 | J72: =H72/$F72 -> 0.54954955
...
