Workbook

Sheet フォームの回答
A1: タイムスタンプ | B1: 問１ あなたは何年生ですか。 | C1: 小中区分 | D1: 問２ 11月22日（ふれあいホリデー）はどのように過ごしましたか。 | E1: 問３ どのように感じましたか。 | F1: 問４ 感想や、これからどうすればいいかを教えてください。
A2: 45624.353 | B2: 中学校３年生 | C2: =LEFT(Form_Responses1[[#This Row],[問１ あなたは何年生ですか。]],3) -> 中学校 | D2: 一人で過ごした | E2: よかった | F2: 休めるました
A3: 45624.51 | B3: 中学校３年生 | C3: =LEFT(Form_Responses1[[#This Row],[問１ あなたは何年生ですか。]],3) -> 中学校 | D3: 子どもだけで家で過ごした（こどもだけでいえですごした） | E3: とてもよかった | F3: 一人はとてもいい
A4: 45624.51 | B4: 中学校３年生 | C4: =LEFT(Form_Responses1[[#This Row],[問１ あなたは何年生ですか。]],3) -> 中学校 | D4: 図書館で勉強した | E4: よかった | F4: 期末テスト前だったため、触れ合うことを中心とするなら日をずらしてほしいと思った。
A5: 45624.51 | B5: 中学校３年生 | C5: =LEFT(Form_Responses1[[#This Row],[問１ あなたは何年生ですか。]],3) -> 中学校 | D5: 子どもだけでイベントに参加した（こどもだけでイベントにさんかした） | E5: とてもよかった | F5: ボランティアに参加したけどすごく楽しかったです。
A6: 45624.512 | B6: 中学校３年生 | C6: =LEFT(Form_Responses1[[#This Row],[問１ あなたは何年生ですか。]],3) -> 中学校 | D6: 家族と倉吉市外に出かけた（かぞくとくらよししがいにでかけた） | E6: よかった | F6: 家族とふれあうことができた
A7: 45624.512 | B7: 中学校３年生 | C7: =LEFT(Form_Responses1[[#This Row],[問１ あなたは何年生ですか。]],3) -> 中学校 | D7: 勉強した | E7: あまりよくなかった | F7: 家族と過ごす
A8: 45624.513 | B8: 中学校３年生 | C8: =LEFT(Form_Responses1[[#This Row],[問１ あなたは何年生ですか。]],3) -> 中学校 | D8: 家族と倉吉市外に出かけた（かぞくとくらよししがいにでかけた） | E8: とてもよかった | F8: とても楽しい時間を過ごせた。祖父母とも旅行を一緒にできて、美味しいものも食べれて良かった。
A9: 45624.514 | B9: 中学校３年生 | C9: =LEFT(Form_Responses1[[#This Row],[問１ あなたは何年生ですか。]],3) -> 中学校 | D9: 子どもだけで家で過ごした（こどもだけでいえですごした） | E9: よかった
A10: 45624.514 | B10: 中学校３年生 | C10: =LEFT(Form_Responses1[[#This Row],[問１ あなたは何年生ですか。]],3) -> 中学校 | D10: 子どもだけでイベントに参加した（こどもだけでイベントにさんかした） | E10: とてもよかった | F10: もっと小学生と関われるボランティアを増やしてほしいです。
A11: 45624.514 | B11: 中学校３年生 | C11: =LEFT(Form_Responses1[[#This Row],[問１ あなたは何年生ですか。]],3) -> 中学校 | D11: 勉強 | E11: よかった | F11: 期末テストで忙しかった
A12: 45624.514 | B12: 中学校３年生 | C12: =LEFT(Form_Responses1[[#This Row],[問１ あなたは何年生ですか。]],3) -> 中学校 | D12: 兄弟とおばあちゃんちに行った | E12: とてもよかった | F12: もっとたくさんあればいいなと思いました。
A13: 45624.514 | B13: 中学校３年生 | C13: =LEFT(Form_Responses1[[#This Row],[問１ あなたは何年生ですか。]],3) -> 中学校 | D13: 家族と家で過ごした（かぞくといえですごした） | E13: とてもよかった | F13: 性感染病や妊娠については気をつけようと思った。
A14: 45624.514 | B14: 中学校３年生 | C14: =LEFT(Form_Responses1[[#This Row],[問１ あなたは何年生ですか。]],3) -> 中学校 | D14: 家族と一緒にイベントに参加した（かぞくといっしょにイベントにさんかした） | E14: とてもよかった | F14: 私は、イベントのボランティアに参加し小学生と交流しました。 普段関わることのできない小学生達と楽しくイベントで関わることのできて とても良かったです！
A15: 45624.514 | B15: 中学校３年生 | C15: =LEFT(Form_Responses1[[#This Row],[問１ あなたは何年生ですか。]],3) -> 中学校 | D15: 上井のボランティア | E15: とてもよかった | F15: ｄｘ；ぺおｆ−「えｐほｖぴｄｐｖ＠おｐｗｄｃ
A16: 45624.514 | B16: 中学校３年生 | C16: =LEFT(Form_Responses1[[#This Row],[問１ あなたは何年生ですか。]],3) -> 中学校 | D16: 家族と家で過ごした（かぞくといえですごした） | E16: とてもよかった
A17: 45624.514 | B17: 中学校３年生 | C17: =LEFT(Form_Responses1[[#This Row],[問１ あなたは何年生ですか。]],3) -> 中学校 | D17: 家族と家で過ごした（かぞくといえですごした） | E17: とてもよかった | F17: もっと増やせばいいと思います
A18: 45624.514 | B18: 中学校３年生 | C18: =LEFT(Form_Responses1[[#This Row],[問１ あなたは何年生ですか。]],3) -> 中学校 | D18: 子どもだけでイベントに参加した（こどもだけでイベントにさんかした） | E18: とてもよかった | F18: もっとふやせばいい
A19: 45624.514 | B19: 中学校３年生 | C19: =LEFT(Form_Responses1[[#This Row],[問１ あなたは何年生ですか。]],3) -> 中学校 | D19: 覚えていない | E19: よかった | F19: 覚えていない
A20: 45624.514 | B20: 中学校３年生 | C20: =LEFT(Form_Responses1[[#This Row],[問１ あなたは何年生ですか。]],3) -> 中学校 | D20: 家族と家で過ごした（かぞくといえですごした） | E20: とてもよかった | F20: 増やして
A21: 45624.515 | B21: 中学校３年生 | C21: =LEFT(Form_Responses1[[#This Row],[問１ あなたは何年生ですか。]],3) -> 中学校 | D21: 子どもだけで家で過ごした（こどもだけでいえですごした） | E21: とてもよかった | F21: 今度は親とすごしてみたいです
A22: 45624.515 | B22: 中学校３年生 | C22: =LEFT(Form_Responses1[[#This Row],[問１ あなたは何年生ですか。]],3) -> 中学校 | D22: 家族と家で過ごした（かぞくといえですごした） | E22: とてもよかった | F22: 普段は仕事や学校で忙しくて家族全員が集まれなかったけどみんなでゲームとかできて良かったのでこれからもこういう時間を取りたいと思いました
A23: 45624.515 | B23: 中学校３年生 | C23: =LEFT(Form_Responses1[[#This Row],[問１ あなたは何年生ですか。]],3) -> 中学校 | D23: 家族と家で過ごした（かぞくといえですごした） | E23: とてもよかった | F23: もっと増やすべき
A24: 45624.515 | B24: 中学校３年生 | C24: =LEFT(Form_Responses1[[#This Row],[問１ あなたは何年生ですか。]],3) -> 中学校 | D24: 家族と家で過ごした（かぞくといえですごした） | E24: とてもよかった
A25: 45624.515 | B25: 中学校３年生 | C25: =LEFT(Form_Responses1[[#This Row],[問１ あなたは何年生ですか。]],3) -> 中学校 | D25: 子どもだけでイベントに参加した（こどもだけでイベントにさんかした） | E25: とてもよかった | F25: 楽しかった
A26: 45624.515 | B26: 中学校３年生 | C26: =LEFT(Form_Responses1[[#This Row],[問１ あなたは何年生ですか。]],3) -> 中学校 | D26: 子どもだけでイベントに参加した（こどもだけでイベントにさんかした） | E26: よかった | F26: 小さい子供と関われて楽しかった
A27: 45624.515 | B27: 中学校３年生 | C27: =LEFT(Form_Responses1[[#This Row],[問１ あなたは何年生ですか。]],3) -> 中学校 | D27: 子どもだけで家で過ごした（こどもだけでいえですごした） | E27: あまりよくなかった | F27: 親が仕事でいなかったから、親も休みにする
A28: 45624.515 | B28: 中学校３年生 | C28: =LEFT(Form_Responses1[[#This Row],[問１ あなたは何年生ですか。]],3) -> 中学校 | D28: 子どもだけで家で過ごした（こどもだけでいえですごした） | E28: とてもよかった
A29: 45624.515 | B29: 中学校３年生 | C29: =LEFT(Form_Responses1[[#This Row],[問１ あなたは何年生ですか。]],3) -> 中学校 | D29: 子どもだけでイベントに参加した（こどもだけでイベントにさんかした） | E29: とてもよかった | F29: 楽しかった
A30: 45624.515 | B30: 中学校３年生 | C30: =LEFT(Form_Responses1[[#This Row],[問１ あなたは何年生ですか。]],3) -> 中学校 | D30: 家族と家で過ごした（かぞくといえですごした） | E30: とてもよかった | F30: いい祝日だと思った。
A31: 45624.515 | B31: 中学校３年生 | C31: =LEFT(Form_Responses1[[#This Row],[問１ あなたは何年生ですか。]],3) -> 中学校 | D31: 家族と家で過ごした（かぞくといえですごした） | E31: とてもよかった | F31: わかりません
A32: 45624.515 | B32: 中学校３年生 | C32: =LEFT(Form_Responses1[[#This Row],[問１ あなたは何年生ですか。]],3) -> 中学校 | D32: 期末に向けて勉強をした | E32: とてもよかった | F32: ふれあいを活発にするためにイベントを開く
A33: 45624.515 | B33: 中学校３年生 | C33: =LEFT(Form_Responses1[[#This Row],[問１ あなたは何年生ですか。]],3) -> 中学校 | D33: 一人でいた | E33: とてもよかった | F33: もっと期間を伸ばしてほしい
A34: 45624.515 | B34: 中学校３年生 | C34: =LEFT(Form_Responses1[[#This Row],[問１ あなたは何年生ですか。]],3) -> 中学校 | D34: 家族と倉吉市外に出かけた（かぞくとくらよししがいにでかけた） | E34: とてもよかった | F34: もっとほしい
A35: 45624.515 | B35: 中学校３年生 | C35: =LEFT(Form_Responses1[[#This Row],[問１ あなたは何年生ですか。]],3) -> 中学校 | D35: 家族と家で過ごした（かぞくといえですごした） | E35: とてもよかった | F35: このような日をもっと増やしてほしいです
A36: 45624.515 | B36: 中学校３年生 | C36: =LEFT(Form_Responses1[[#This Row],[問１ あなたは何年生ですか。]],3) -> 中学校 | D36: 家族と家で過ごした（かぞくといえですごした） | E36: とてもよかった | F36: とても良かった。
A37: 45624.515 | B37: 中学校３年生 | C37: =LEFT(Form_Responses1[[#This Row],[問１ あなたは何年生ですか。]],3) -> 中学校 | D37: おじいちゃんと一緒に昼ご飯を作りました。 | E37: とてもよかった | F37: もうちょっと増やせばいいかな？と感じました。
A38: 45624.516 | B38: 中学校３年生 | C38: =LEFT(Form_Responses1[[#This Row],[問１ あなたは何年生ですか。]],3) -> 中学校 | D38: お勉強 | E38: よくなかった | F38: 休みは嬉しい
A39: 45624.516 | B39: 中学校３年生 | C39: =LEFT(Form_Responses1[[#This Row],[問１ あなたは何年生ですか。]],3) -> 中学校 | D39: 家族と家で過ごした（かぞくといえですごした） | E39: とてもよかった | F39: テスト期間だったので、みっちり勉強できたし、せっかくホリデーだからおばあちゃんちで勉強して、おばあちゃんがたまにお菓子持ってきてくれてホリデーだなと思いました。
A40: 45624.516 | B40: 中学校３年生 | C40: =LEFT(Form_Responses1[[#This Row],[問１ あなたは何年生ですか。]],3) -> 中学校 | D40: 家族と家で過ごした（かぞくといえですごした） | E40: よかった | F40: これからも関わる習慣をつけていきたいです
...

Sheet Sheet1
B1: 児童生徒
B2: 問２ 11月22日（ふれあいホリデー）はどのように過ごしましたか。
B3: 小中 | C3: 家族と家で過ごした（かぞくといえですごした） | D3: 家族と一緒にイベントに参加した（かぞくといっしょにイベントにさんかした） | E3: 家族と倉吉市内に出かけた（かぞくとくらよししないにでかけた） | F3: 家族と倉吉市外に出かけた（かぞくとくらよししがいにでかけた） | G3: 親戚や知り合いと過ごした（しんせきやしりあいとすごした） | H3: 子どもだけで家で過ごした（こどもだけでいえですごした） | I3: 子どもだけで地域で過ごした（こどもだけでちいきですごした） | J3: 子どもだけでイベントに参加した（こどもだけでイベントにさんかした） | K3: 児童館、放課後児童クラブなどで過ごした（じどうかん、ほうかごじどうクラブなどですごした） | L3: その他 | M3: 合計
B4: 小学校 | C4: =COUNTIFS(フォームの回答!$C$2:$C$2349,$B4,フォームの回答!$D$2:$D$2349,C$3) -> 513 | D4: =COUNTIFS(フォームの回答!$C$2:$C$2349,$B4,フォームの回答!$D$2:$D$2349,D$3) -> 68 | E4: =COUNTIFS(フォームの回答!$C$2:$C$2349,$B4,フォームの回答!$D$2:$D$2349,E$3) -> 106 | F4: =COUNTIFS(フォームの回答!$C$2:$C$2349,$B4,フォームの回答!$D$2:$D$2349,F$3) -> 263 | G4: =COUNTIFS(フォームの回答!$C$2:$C$2349,$B4,フォームの回答!$D$2:$D$2349,G$3) -> 64 | H4: =COUNTIFS(フォームの回答!$C$2:$C$2349,$B4,フォームの回答!$D$2:$D$2349,H$3) -> 135 | I4: =COUNTIFS(フォームの回答!$C$2:$C$2349,$B4,フォームの回答!$D$2:$D$2349,I$3) -> 30 | J4: =COUNTIFS(フォームの回答!$C$2:$C$2349,$B4,フォームの回答!$D$2:$D$2349,J$3) -> 42 | K4: =COUNTIFS(フォームの回答!$C$2:$C$2349,$B4,フォームの回答!$D$2:$D$2349,K$3) -> 118 | L4: =M4-SUM(C4:K4) -> 140 | M4: =COUNTIFS(フォームの回答!$C$2:$C$2349,$B4) -> 1479
B5: 中学校 | C5: =COUNTIFS(フォームの回答!$C$2:$C$2349,$B5,フォームの回答!$D$2:$D$2349,C$3) -> 321 | D5: =COUNTIFS(フォームの回答!$C$2:$C$2349,$B5,フォームの回答!$D$2:$D$2349,D$3) -> 9 | E5: =COUNTIFS(フォームの回答!$C$2:$C$2349,$B5,フォームの回答!$D$2:$D$2349,E$3) -> 50 | F5: =COUNTIFS(フォームの回答!$C$2:$C$2349,$B5,フォームの回答!$D$2:$D$2349,F$3) -> 71 | G5: =COUNTIFS(フォームの回答!$C$2:$C$2349,$B5,フォームの回答!$D$2:$D$2349,G$3) -> 18 | H5: =COUNTIFS(フォームの回答!$C$2:$C$2349,$B5,フォームの回答!$D$2:$D$2349,H$3) -> 208 | I5: =COUNTIFS(フォームの回答!$C$2:$C$2349,$B5,フォームの回答!$D$2:$D$2349,I$3) -> 42 | J5: =COUNTIFS(フォームの回答!$C$2:$C$2349,$B5,フォームの回答!$D$2:$D$2349,J$3) -> 19 | K5: =COUNTIFS(フォームの回答!$C$2:$C$2349,$B5,フォームの回答!$D$2:$D$2349,K$3) -> 5 | L5: =M5-SUM(C5:K5) -> 126 | M5: =COUNTIFS(フォームの回答!$C$2:$C$2349,$B5) -> 869
B6: 全体 | C6: =SUM(C4:C5) -> 834 | D6: =SUM(D4:D5) -> 77 | E6: =SUM(E4:E5) -> 156 | F6: =SUM(F4:F5) -> 334 | G6: =SUM(G4:G5) -> 82 | H6: =SUM(H4:H5) -> 343 | I6: =SUM(I4:I5) -> 72 | J6: =SUM(J4:J5) -> 61 | ... M6: =SUM(M4:M5) -> 2348
B7: 小学校 | C7: =C4/$M4 -> 0.34685598 | D7: =D4/$M4 -> 0.045977011 | E7: =E4/$M4 -> 0.071670047 | F7: =F4/$M4 -> 0.17782285 | G7: =G4/$M4 -> 0.043272481 | H7: =H4/$M4 -> 0.09127789 | I7: =I4/$M4 -> 0.020283976 | J7: =J4/$M4 -> 0.028397566 | ... L7: =L4/$M4 -> 0.094658553
B8: 中学校 | C8: =C5/$M5 -> 0.3693901 | D8: =D5/$M5 -> 0.010356732 | E8: =E5/$M5 -> 0.057537399 | F8: =F5/$M5 -> 0.081703107 | G8: =G5/$M5 -> 0.020713464 | H8: =H5/$M5 -> 0.23935558 | I8: =I5/$M5 -> 0.048331415 | J8: =J5/$M5 -> 0.021864212 | ... L8: =L5/$M5 -> 0.14499425
B11: 問３ どのように感じましたか。
B12: 小中 | C12: とてもよかった | D12: よかった | E12: あまりよくなかった | F12: よくなかった | G12: 合計
B13: 小学校 | C13: =COUNTIFS(フォームの回答!$C$2:$C$2349,$B13,フォームの回答!$E$2:$E$2349,C$12) -> 988 | D13: =COUNTIFS(フォームの回答!$C$2:$C$2349,$B13,フォームの回答!$E$2:$E$2349,D$12) -> 392 | E13: =COUNTIFS(フォームの回答!$C$2:$C$2349,$B13,フォームの回答!$E$2:$E$2349,E$12) -> 65 | F13: =COUNTIFS(フォームの回答!$C$2:$C$2349,$B13,フォームの回答!$E$2:$E$2349,F$12) -> 34 | G13: =SUM(C13:F13) -> 1479
B14: 中学校 | C14: =COUNTIFS(フォームの回答!$C$2:$C$2349,$B14,フォームの回答!$E$2:$E$2349,C$12) -> 554 | D14: =COUNTIFS(フォームの回答!$C$2:$C$2349,$B14,フォームの回答!$E$2:$E$2349,D$12) -> 264 | E14: =COUNTIFS(フォームの回答!$C$2:$C$2349,$B14,フォームの回答!$E$2:$E$2349,E$12) -> 36 | F14: =COUNTIFS(フォームの回答!$C$2:$C$2349,$B14,フォームの回答!$E$2:$E$2349,F$12) -> 15 | G14: =SUM(C14:F14) -> 869
B15: 全体 | C15: =SUM(C13:C14) -> 1542 | D15: =SUM(D13:D14) -> 656 | E15: =SUM(E13:E14) -> 101 | F15: =SUM(F13:F14) -> 49 | G15: =SUM(G13:G14) -> 2348
B16: 小学校 | C16: =C13/$G13 -> 0.66801893 | D16: =D13/$G13 -> 0.26504395 | E16: =E13/$G13 -> 0.043948614 | F16: =F13/$G13 -> 0.022988506
B17: 中学校 | C17: =C14/$G14 -> 0.63751438 | D17: =D14/$G14 -> 0.30379747 | E17: =E14/$G14 -> 0.041426928 | F17: =F14/$G14 -> 0.01726122

Sheet 見せ方を変えたの
D3: 【児童生徒】
D5: 11月22日（ふれあいホリデー）はどのように過ごしましたか。
D6: № | E6: 選択肢 | F6: 実数 | I6: 率
F7: 全体 | G7: 小学校 | H7: 中学校 | I7: 全体 | J7: 小学校 | K7: 中学校
D8: 1 | E8: 家族と家で過ごした | F8: 834 | G8: 513 | H8: 321 | I8: 0.35519591 | J8: =G8/G$18 -> 0.34685598 | K8: =H8/H$18 -> 0.3693901
D9: 2 | E9: 家族と一緒にイベントに参加した | F9: 77 | G9: 68 | H9: 9 | I9: 0.032793867 | J9: =G9/G$18 -> 0.045977011 | K9: =H9/H$18 -> 0.010356732
D10: 3 | E10: 家族と倉吉市内に出かけた | F10: 156 | G10: 106 | H10: 50 | I10: 0.066439523 | J10: =G10/G$18 -> 0.071670047 | K10: =H10/H$18 -> 0.057537399
D11: 4 | E11: 家族と倉吉市外に出かけた | F11: 334 | G11: 263 | H11: 71 | I11: 0.14224872 | J11: =G11/G$18 -> 0.17782285 | K11: =H11/H$18 -> 0.081703107
D12: 5 | E12: 親戚や知り合いと過ごした | F12: 82 | G12: 64 | H12: 18 | I12: 0.034923339 | J12: =G12/G$18 -> 0.043272481 | K12: =H12/H$18 -> 0.020713464
D13: 6 | E13: 子どもだけで家で過ごした | F13: 343 | G13: 135 | H13: 208 | I13: 0.14608177 | J13: =G13/G$18 -> 0.09127789 | K13: =H13/H$18 -> 0.23935558
D14: 7 | E14: 子どもだけで地域で過ごした | F14: 72 | G14: 30 | H14: 42 | I14: 0.030664395 | J14: =G14/G$18 -> 0.020283976 | K14: =H14/H$18 -> 0.048331415
D15: 8 | E15: 子どもだけでイベントに参加した | F15: 61 | G15: 42 | H15: 19 | I15: 0.025979557 | J15: =G15/G$18 -> 0.028397566 | K15: =H15/H$18 -> 0.021864212
D16: 9 | E16: 児童館、放課後児童クラブなどで過ごした | F16: 123 | G16: 118 | H16: 5 | I16: 0.052385009 | J16: =G16/G$18 -> 0.079783638 | K16: =H16/H$18 -> 0.0057537399
D17: 10 | E17: その他 | F17: 266 | G17: 140 | H17: 126 | I17: 0.1132879 | J17: =G17/G$18 -> 0.094658553 | K17: =H17/H$18 -> 0.14499425
E18: 合計 | F18: 2348 | G18: 1479 | H18: 869 | I18: 1 | J18: 1 | K18: 1
D21: どのように感じましたか。
D22: № | E22: 選択肢 | F22: 実数 | I22: 率
F23: 全体 | G23: 小学校 | H23: 中学校 | I23: 全体 | J23: 小学校 | K23: 中学校
D24: 1 | E24: とてもよかった | F24: 1542 | G24: 988 | H24: 554 | I24: =F24/F$28 -> 0.65672913 | J24: 0.66801893 | K24: 0.63751438
D25: 2 | E25: よかった | F25: 656 | G25: 392 | H25: 264 | I25: =F25/F$28 -> 0.27938671 | J25: 0.26504395 | K25: 0.30379747
D26: 3 | E26: あまりよくなかった | F26: 101 | G26: 65 | H26: 36 | I26: =F26/F$28 -> 0.043015332 | J26: 0.043948614 | K26: 0.041426928
D27: 4 | E27: よくなかった | F27: 49 | G27: 34 | H27: 15 | I27: =F27/F$28 -> 0.020868825 | J27: 0.022988506 | K27: 0.01726122
E28: 合計 | F28: 2348 | G28: 1479 | H28: 869 | I28: 1 | J28: 1 | K28: 1
